<?xml version="1.0" ?>
<!-- =================================================================================== -->
<!-- |    This document was autogenerated by xacro from mg400_description/urdf/mg400_description.urdf.xacro | -->
<!-- |    EDITING THIS FILE BY HAND IS NOT RECOMMENDED                                 | -->
<!-- =================================================================================== -->
<robot name="mg400">
  <material name="black">
    <color rgba="0.0 0.0 0.0 1.0"/>
  </material>
  <material name="grey">
    <color rgba="0.2 0.2 0.2 1.0"/>
  </material>
  <material name="light-grey">
    <color rgba="0.6 0.6 0.6 1.0"/>
  </material>
  <material name="orange">
    <color rgba="1.0 0.4235294117647059 0.0392156862745098 1.0"/>
  </material>
  <material name="brown">
    <color rgba="0.8705882352941177 0.8117647058823529 0.7647058823529411 1.0"/>
  </material>
  <material name="white">
    <color rgba="1.0 1.0 1.0 1.0"/>
  </material>
  <material name="red">
    <color rgba="0.8 0.0 0.0 1.0"/>
  </material>
  <material name="blue">
    <color rgba="0.0 0.0 0.8 1.0"/>
  </material>
  <material name="green">
    <color rgba="0.0 0.8 0.0 1.0"/>
  </material>
  <material name="yellow">
    <color rgba="0.9725490196078431 0.7098039215686275 0.0 1.0"/>
  </material>
  <material name="transparent-black">
    <color rgba="0.0 0.0 0.0 0.2"/>
  </material>
  <material name="transparent-red">
    <color rgba="0.8 0.0 0.0 0.2"/>
  </material>
  <material name="transparent-blue">
    <color rgba="0.0 0.0 0.8 0.2"/>
  </material>
  <material name="transparent-green">
    <color rgba="0.0 0.8 0.0 0.2"/>
  </material>
  <material name="transparent-yellow">
    <color rgba="0.9725490196078431 0.7098039215686275 0.0 0.2"/>
  </material>
  <material name="transparent-grey">
    <color rgba="0.2 0.2 0.2 0.2"/>
  </material>
  <material name="transparent-light-grey">
    <color rgba="0.6 0.6 0.6 0.2"/>
  </material>
  <link name="base_link">
    <inertial>
      <origin rpy="0 0 0" xyz="0.000600637001378879 -2.53487071137343E-07 0.0560927888040551"/>
      <mass value="3.62164811695094"/>
      <inertia ixx="0.0126582175296405" ixy="6.66832041405407E-08" ixz="-3.52548281362717E-06" iyy="0.0145891535260188" iyz="5.15901657460475E-08" izz="0.0195045116656827"/>
    </inertial>
    <visual>
      <origin rpy="0 0 0" xyz="0 0 0"/>
      <geometry>
        <mesh filename="package://mg400_description/meshes/base_link.stl"/>
      </geometry>
      <material name="white"/>
    </visual>
    <collision>
      <origin rpy="0 0 0" xyz="0 0 0"/>
      <geometry>
        <mesh filename="package://mg400_description/meshes/base_link.stl"/>
      </geometry>
    </collision>
  </link>
  <link name="link1">
    <inertial>
      <origin rpy="0 0 0" xyz="-0.0046209286967387 -6.88107982318643E-05 0.0709919358465827"/>
      <mass value="1.77056222753813"/>
      <inertia ixx="0.00605885293080088" ixy="0.000156081820035162" ixz="-0.00021785654850453" iyy="0.00579381982249127" iyz="6.20876898015621E-05" izz="0.00741058257251941"/>
    </inertial>
    <visual>
      <origin rpy="0 0 0" xyz="0 0 0"/>
      <geometry>
        <mesh filename="package://mg400_description/meshes/link1.stl"/>
      </geometry>
      <material name="grey"/>
    </visual>
    <collision>
      <origin rpy="0 0 0" xyz="0 0 0"/>
      <geometry>
        <mesh filename="package://mg400_description/meshes/link1.stl"/>
      </geometry>
    </collision>
  </link>
  <joint name="j1" type="revolute">
    <origin rpy="0 0 0" xyz="-0.005 0 0.109"/>
    <parent link="base_link"/>
    <child link="link1"/>
    <axis xyz="0 0 1"/>
    <limit effort="0" lower="-3.141592653589793" upper="3.141592653589793" velocity="0"/>
  </joint>
  <link name="link2_1">
    <inertial>
      <origin rpy="0 0 0" xyz="-0.00321788524756698 0.0352926570826593 0.0596131328734945"/>
      <mass value="0.0866115884541459"/>
      <inertia ixx="0.000338551627157209" ixy="-2.78858228577314E-09" ixz="1.05212346076681E-05" iyy="0.000307789653713489" iyz="-1.36109590152488E-06" izz="3.89949940178023E-05"/>
    </inertial>
    <visual>
      <origin rpy="0 0 0" xyz="0 0 0"/>
      <geometry>
        <mesh filename="package://mg400_description/meshes/link2_1.stl"/>
      </geometry>
      <material name="black"/>
    </visual>
    <collision>
      <origin rpy="0 0 0" xyz="0 0 0"/>
      <geometry>
        <mesh filename="package://mg400_description/meshes/link2_1.stl"/>
      </geometry>
    </collision>
  </link>
  <joint name="j2_1" type="revolute">
    <origin rpy="0 0 0" xyz="0.0435007595118091 -0.0357748756218899 0.118995682641123"/>
    <parent link="link1"/>
    <child link="link2_1"/>
    <axis xyz="0 1 0"/>
    <limit effort="0" lower="-3.14" upper="3.14" velocity="0"/>
  </joint>
  <link name="link3_1">
    <inertial>
      <origin rpy="0 0 0" xyz="0.0821679417596488 0.000113044685842874 -0.00333758753063973"/>
      <mass value="0.0375214831045061"/>
      <inertia ixx="2.54761091812684E-06" ixy="3.73102654491378E-07" ixz="-2.02625705871199E-06" iyy="0.000164234314177935" iyz="-1.44731096825347E-08" izz="0.000164331500854172"/>
    </inertial>
    <visual>
      <origin rpy="0 0 0" xyz="0 0 0"/>
      <geometry>
        <mesh filename="package://mg400_description/meshes/link3_1.stl"/>
      </geometry>
      <material name="black"/>
    </visual>
    <collision>
      <origin rpy="0 0 0" xyz="0 0 0"/>
      <geometry>
        <mesh filename="package://mg400_description/meshes/link3_1.stl"/>
      </geometry>
    </collision>
  </link>
  <joint name="j3_1" type="revolute">
    <origin rpy="0 0 0" xyz="-0.0010512570171516 0.0357748756218898 0.175001164344716"/>
    <parent link="link2_1"/>
    <child link="link3_1"/>
    <axis xyz="0 1 0"/>
    <limit effort="0" lower="-3.14" upper="3.14" velocity="0"/>
  </joint>
  <link name="link4_1">
    <inertial>
      <origin rpy="0 0 0" xyz="0.0387878182928232 0.0170848333998282 -0.0024610990490942"/>
      <mass value="0.0628979533925801"/>
      <inertia ixx="4.78483605712844E-05" ixy="1.42081909356751E-07" ixz="8.32917079044309E-06" iyy="5.42362047732042E-05" iyz="-2.90608446019989E-08" izz="3.36120409842199E-05"/>
    </inertial>
    <visual>
      <origin rpy="0 0 0" xyz="0 0 0"/>
      <geometry>
        <mesh filename="package://mg400_description/meshes/link4_1.stl"/>
      </geometry>
      <material name="white"/>
    </visual>
    <collision>
      <origin rpy="0 0 0" xyz="0 0 0"/>
      <geometry>
        <mesh filename="package://mg400_description/meshes/link4_1.stl"/>
      </geometry>
    </collision>
  </link>
  <joint name="j4_1" type="revolute">
    <origin rpy="0 0 0" xyz="0.174969784055705 -0.0170000000000335 0.00325187137614585"/>
    <parent link="link3_1"/>
    <child link="link4_1"/>
    <axis xyz="0 1 0"/>
    <limit effort="0" lower="-3.14" upper="3.14" velocity="0"/>
  </joint>
  <link name="link5">
    <inertial>
      <origin rpy="0 0 0" xyz="4.24246458685662E-07 3.08507851181768E-14 -0.0349688816440933"/>
      <mass value="0.0965276919819365"/>
      <inertia ixx="4.98589992160928E-05" ixy="-1.534865545378E-12" ixz="3.46424449605658E-10" iyy="4.98589881725446E-05" iyz="-5.64890953414983E-17" izz="2.130463008359E-05"/>
    </inertial>
    <visual>
      <origin rpy="0 0 0" xyz="0 0 0"/>
      <geometry>
        <mesh filename="package://mg400_description/meshes/link5.stl"/>
      </geometry>
      <material name="grey"/>
    </visual>
    <collision>
      <origin rpy="0 0 0" xyz="0 0 0"/>
      <geometry>
        <mesh filename="package://mg400_description/meshes/link5.stl"/>
      </geometry>
    </collision>
  </link>
  <joint name="j5_1" type="fixed">
    <origin rpy="0 0 0" xyz="0.0659996239003897 0.0170000000000371 0.031000800715573"/>
    <parent link="link4_1"/>
    <child link="link5"/>
    <axis xyz="0 0 1"/>
  </joint>
  <link name="end_effector_shaft">
    <visual>
      <origin rpy="0 0 0" xyz="0 0 0"/>
      <geometry>
        <cylinder length="0.015" radius="0.004"/>
      </geometry>
      <material name="red"/>
    </visual>
    <collision>
      <origin rpy="0 0 0" xyz="0 0 0"/>
      <geometry>
        <cylinder length="0.015" radius="0.004"/>
      </geometry>
    </collision>
  </link>
  <joint name="j5" type="revolute">
    <origin rpy="0 0 0" xyz="0 0 -0.07"/>
    <parent link="link5"/>
    <child link="end_effector_shaft"/>
    <axis xyz="0 0 1"/>
    <limit effort="0" lower="-3.141592653589793" upper="3.141592653589793" velocity="0"/>
  </joint>
  <link name="link2_2">
    <inertial>
      <origin rpy="0 0 0" xyz="-0.0201111131723385 0.0304999635268521 0.073632809340276"/>
      <mass value="0.0662546292985346"/>
      <inertia ixx="0.000218973873589181" ixy="3.0147933007673E-10" ixz="2.51402553227571E-06" iyy="0.000200510070261609" iyz="-1.41837669904595E-09" izz="3.74316777806776E-05"/>
    </inertial>
    <visual>
      <origin rpy="0 0 0" xyz="0 0 0"/>
      <geometry>
        <mesh filename="package://mg400_description/meshes/link2_2.stl"/>
      </geometry>
      <material name="white"/>
    </visual>
    <collision>
      <origin rpy="0 0 0" xyz="0 0 0"/>
      <geometry>
        <mesh filename="package://mg400_description/meshes/link2_2.stl"/>
      </geometry>
    </collision>
  </link>
  <joint name="j2_2" type="revolute">
    <origin rpy="0 0 0" xyz="0.00452885682964267 -0.0305 0.141500000000001"/>
    <parent link="link1"/>
    <child link="link2_2"/>
    <axis xyz="0 1 0"/>
    <limit effort="0" lower="-3.14" upper="3.14" velocity="0"/>
  </joint>
  <link name="link3_2">
    <inertial>
      <origin rpy="0 0 0" xyz="0.0338566736074436 0.0240208873857428 0.00452229895926692"/>
      <mass value="0.0366692789294813"/>
      <inertia ixx="7.24011830695354E-06" ixy="7.93542746250724E-10" ixz="-1.69163254472566E-06" iyy="2.34967008246727E-05" iyz="4.55507111386579E-10" izz="1.66831643179488E-05"/>
    </inertial>
    <visual>
      <origin rpy="0 0 0" xyz="0 0 0"/>
      <geometry>
        <mesh filename="package://mg400_description/meshes/link3_2.stl"/>
      </geometry>
      <material name="black"/>
    </visual>
    <collision>
      <origin rpy="0 0 0" xyz="0 0 0"/>
      <geometry>
        <mesh filename="package://mg400_description/meshes/link3_2.stl"/>
      </geometry>
    </collision>
  </link>
  <joint name="j3_2" type="revolute">
    <origin rpy="0 0 0" xyz="-0.00105049750546494 0.00649999999999986 0.174996846985851"/>
    <parent link="link2_2"/>
    <child link="link3_2"/>
    <axis xyz="0 1 0"/>
    <limit effort="0" lower="-3.14" upper="3.14" velocity="0"/>
  </joint>
  <link name="link4_2">
    <inertial>
      <origin rpy="0 0 0" xyz="0.0876391591012518 0.023499867452275 0.00831492252441945"/>
      <mass value="0.0453569016333092"/>
      <inertia ixx="2.00037596001325E-05" ixy="3.34474706250153E-09" ixz="2.17594982354756E-07" iyy="0.000132049841023893" iyz="5.36978669669685E-10" izz="0.000141813978894428"/>
    </inertial>
    <visual>
      <origin rpy="0 0 0" xyz="0 0 0"/>
      <geometry>
        <mesh filename="package://mg400_description/meshes/link4_2.stl"/>
      </geometry>
      <material name="white"/>
    </visual>
    <collision>
      <origin rpy="0 0 0" xyz="0 0 0"/>
      <geometry>
        <mesh filename="package://mg400_description/meshes/link4_2.stl"/>
      </geometry>
    </collision>
  </link>
  <joint name="j4_2" type="revolute">
    <origin rpy="0 0 0" xyz="0.0678965856063864 0.000500000000000073 0.0119719999403219"/>
    <parent link="link3_2"/>
    <child link="link4_2"/>
    <axis xyz="0 1 0"/>
    <limit effort="0" lower="-3.14" upper="3.14" velocity="0"/>
  </joint>
</robot>
